Workbook

Sheet Resumo
A1: Victor Guilherme — PROD1 · aparelhos (api-rastreio-imei + relatorio-reparo, 15/10/2026)
A2: Inclui: tudo que está nos endereços PROD1 e PROD1 PRONTO + reparos abertos (em execução/pausados) no nome do Victor em outros endereços.
A4: Endereço | B4: Situação | C4: Qtd
A5: PROD1 | B5: Aguardando gestão de peças | C5: =COUNTIFS(Aparelhos!A:A,A5,Aparelhos!B:B,B5) -> 1
A6: PROD1 | B6: Aguardando técnico iniciar | C6: =COUNTIFS(Aparelhos!A:A,A6,Aparelhos!B:B,B6) -> 20
A7: PROD1 | B7: Em reparo agora | C7: =COUNTIFS(Aparelhos!A:A,A7,Aparelhos!B:B,B7) -> 2
A8: PROD1 | B8: Pausado | C8: =COUNTIFS(Aparelhos!A:A,A8,Aparelhos!B:B,B8) -> 4
A9: PROD1 | B9: Pausado - pedido de peça | C9: =COUNTIFS(Aparelhos!A:A,A9,Aparelhos!B:B,B9) -> 1
A10: PROD1 | B10: Recebido - aguardando reparo | C10: =COUNTIFS(Aparelhos!A:A,A10,Aparelhos!B:B,B10) -> 9
A11: PROD1 | B11: Reparado - aguardando CQE | C11: =COUNTIFS(Aparelhos!A:A,A11,Aparelhos!B:B,B11) -> 8
A12: PROD1 | B12: Reprovado CQE - aguardando retrabalho | C12: =COUNTIFS(Aparelhos!A:A,A12,Aparelhos!B:B,B12) -> 1
A13: PROD1 PRONTO | B13: Aguardando técnico iniciar | C13: =COUNTIFS(Aparelhos!A:A,A13,Aparelhos!B:B,B13) -> 1
A14: PROD1 PRONTO | B14: Finalizado (aprovado CQE) | C14: =COUNTIFS(Aparelhos!A:A,A14,Aparelhos!B:B,B14) -> 9
A15: PROD1 PRONTO | B15: Pausado | C15: =COUNTIFS(Aparelhos!A:A,A15,Aparelhos!B:B,B15) -> 2
A16: PROD1 PRONTO | B16: Reparado - aguardando CQE | C16: =COUNTIFS(Aparelhos!A:A,A16,Aparelhos!B:B,B16) -> 32
... A26: SALA RECEBIMENTO | B26: Pausado | C26: =COUNTIFS(Aparelhos!A:A,A26,Aparelhos!B:B,B26) -> 1
A27: Total | C27: =SUM(C5:C26) -> 112

Sheet Aparelhos
A1: Endereço atual | B1: Situação | C1: Status WMS | D1: IMEI | E1: OS | F1: NF | G1: Aparelho | H1: Técnico do reparo | I1: Status reparo | J1: Entrada no endereço | K1: Início reparo | L1: Última pausa | M1: Fim reparo | N1: CQE | O1: Peças pedidas
A2: PROD1 | B2: Aguardando gestão de peças | C2: AGUARDANDO_GESTAO_PECAS | D2: 350603385685083 | E2: OS005380 | F2: 326518 | G2: SAMSUNG GALAXY A53 5G 128GB WHITE | I2: em_gestao_pecas | J2: 28/09/2026 06:44
A3: PROD1 | B3: Aguardando técnico iniciar | C3: EM_REPARO | D3: 356003105288389 | E3: OS004303 | F3: 308797 | G3: SAMSUNG GALAXY A70 | I3: aguardando_inicio | J3: 28/09/2026 06:43
A4: PROD1 | B4: Aguardando técnico iniciar | C4: EM_REPARO | D4: 358866080539754 | E4: OS004524 | F4: 308797 | G4: SAMSUNG GALAXY J5 PRIME | I4: aguardando_inicio | J4: 28/09/2026 06:43 | O4: TELA SAMSUNG J5 PRIME - G570 - SEM ARO - SKYTECH PRO - BRANCO / CARCACA + TAMPA SAMSUNG A50 - PRETO / CARCACA SAMSUNG J5 PRIME - ROSA / CONECTOR DE CARGA SAMSUNG J1 - J3 - J4 - J4 CORE - J5 - J5 PRIME - J5 PRO - J6 - J6 PLUS - J7 - J7 P
A5: PROD1 | B5: Aguardando técnico iniciar | C5: EM_REPARO | D5: 356450526533952 | E5: OS004968 | F5: 328264 | G5: SAMSUNG SM-A145M GALAXY A14 128GB PRATA | I5: aguardando_inicio | J5: 28/09/2026 06:44
A6: PROD1 | B6: Aguardando técnico iniciar | C6: EM_REPARO | D6: 354103130786365 | E6: OS005904 | F6: 325351 | G6: SAMSUNG GALAXY S22 128GB BLACK | I6: aguardando_inicio | J6: 28/09/2026 06:44
A7: PROD1 | B7: Aguardando técnico iniciar | C7: EM_REPARO | D7: 354680116226037 | E7: OS008061 | F7: 66686 | G7: SAMSUNG GALAXY S20 128GB BLUE | I7: aguardando_inicio | J7: 02/10/2026 10:02 | O7: TELA SAMSUNG S20 - COM ARO - SKYTECH PRO - PRETO / TAMPA SAMSUNG S20 - PRETO / GAVETA DE CHIP SAMSUNG S20 - PRETO
A8: PROD1 | B8: Aguardando técnico iniciar | C8: EM_REPARO | D8: 354711350709949 | E8: OS008343 | F8: 1950194 | G8: SAMSUNG SM-S908E GALAXY S22 ULTRA 5G 256GB PRETO RECERTIFICADO | I8: aguardando_inicio | J8: 08/10/2026 14:05 | O8: TELA SAMSUNG S22 ULTRA 5G - COM ARO - SKYTECH PRO - PRETO / BATERIA SAMSUNG GALAXY S22 ULTRA (EB-BS908ABY) - DEJI
A9: PROD1 | B9: Aguardando técnico iniciar | C9: EM_REPARO | D9: 351371810287797 | E9: OS008393 | F9: 1950193 | G9: SAMSUNG GALAXY S23 ULTRA 256GB SM-S918B PRETO RECERTIFICADO | I9: aguardando_inicio | J9: 08/10/2026 15:31 | O9: BATERIA SAMSUNG GALAXY S23 ULTRA (EB-BS918ABY) / TELA SAMSUNG S23 ULTRA - COM ARO - SKYTECH PRO - PRETO
A10: PROD1 | B10: Aguardando técnico iniciar | C10: EM_REPARO | D10: 351371810646521 | E10: OS008397 | F10: 1950193 | G10: SAMSUNG GALAXY S23 ULTRA 256GB SM-S918B VERDE RECERTIFICADO | I10: aguardando_inicio | J10: 08/10/2026 15:34 | O10: BATERIA SAMSUNG GALAXY S23 ULTRA (EB-BS918ABY) - NACIONAL
A11: PROD1 | B11: Aguardando técnico iniciar | C11: EM_REPARO | D11: 351371810208702 | E11: OS008401 | F11: 1950194 | G11: SAMSUNG GALAXY S23 ULTRA 256GB SM-S918B VERDE RECERTIFICADO | I11: aguardando_inicio | J11: 08/10/2026 15:38 | O11: BATERIA SAMSUNG GALAXY S23 ULTRA (EB-BS918ABY) - AMAZON / TAMPA SAMSUNG S23 ULTRA 5G - VERDE ESCURO / TELA SAMSUNG S23 ULTRA - COM ARO - SKYTECH PRO - VERDE
A12: PROD1 | B12: Aguardando técnico iniciar | C12: EM_REPARO | D12: 350175610417780 | E12: OS008451 | F12: 1950192 | G12: SM-S918BZAKZTO TELEFONE CELULAR SAMSUNG GALAXY S23 ULTRA 256GB S918B GRAFITE RECERTIFICADO EAN: 7894892050129 | I12: aguardando_inicio | J12: 08/10/2026 16:12 | O12: BATERIA SAMSUNG GALAXY S23 ULTRA (EB-BS918ABY)
A13: PROD1 | B13: Aguardando técnico iniciar | C13: EM_REPARO | D13: 350828560834780 | E13: OS008455 | F13: 1950192 | G13: SAMSUNG GALAXY S23 ULTRA 512GB SM-S918B VERDE RECERTIFICADO | I13: aguardando_inicio | J13: 08/10/2026 16:14 | O13: BATERIA SAMSUNG GALAXY S23 ULTRA (EB-BS918ABY)
A14: PROD1 | B14: Aguardando técnico iniciar | C14: EM_REPARO | D14: 350175611175502 | E14: OS008465 | F14: 1950192 | G14: SAMSUNG GALAXY S23 ULTRA 256GB SM-S918B PRETO RECERTIFICADO | I14: aguardando_inicio | J14: 08/10/2026 16:20 | O14: BATERIA SAMSUNG GALAXY S23 ULTRA (EB-BS918ABY) / TELA SAMSUNG S23 ULTRA - COM ARO - SKYTECH PRO - PRETO
A15: PROD1 | B15: Aguardando técnico iniciar | C15: EM_REPARO | D15: 350175610391688 | E15: OS008468 | F15: 1950192 | G15: SAMSUNG GALAXY S23 ULTRA 256GB SM-S918B PRETO RECERTIFICADO | I15: aguardando_inicio | J15: 08/10/2026 16:21 | O15: CAMERA FRONTAL SAMSUNG S23 ULTRA
A16: PROD1 | B16: Aguardando técnico iniciar | C16: EM_REPARO | D16: 350175611075850 | E16: OS008479 | F16: 1950192 | G16: SAMSUNG GALAXY S23 ULTRA 256GB SM-S918B PRETO RECERTIFICADO | I16: aguardando_inicio | J16: 08/10/2026 16:29
A17: PROD1 | B17: Aguardando técnico iniciar | C17: EM_REPARO | D17: 350175610349256 | E17: OS008530 | F17: 1950192 | G17: SAMSUNG GALAXY S23 ULTRA 256GB SM-S918B VERDE RECERTIFICADO | I17: aguardando_inicio | J17: 08/10/2026 16:50
A18: PROD1 | B18: Aguardando técnico iniciar | C18: EM_REPARO | D18: 350175610099547 | E18: OS008538 | F18: 1950192 | G18: SM-S918BLIKZTO TELEFONE CELULAR SAMSUNG GALAXY S23 256GB SM-S918B BRANCO RECERTIFICADO EAN: 7894892046726 | I18: aguardando_inicio | J18: 08/10/2026 16:52 | O18: BATERIA SAMSUNG GALAXY S23 ULTRA (EB-BS918ABY)
A19: PROD1 | B19: Aguardando técnico iniciar | C19: EM_REPARO | D19: 351371810276121 | E19: OS008546 | F19: 1950192 | G19: SAMSUNG GALAXY S23 ULTRA 256GB SM-S918B PRETO RECERTIFICADO | I19: aguardando_inicio | J19: 08/10/2026 16:57 | O19: BATERIA SAMSUNG GALAXY S23 ULTRA (EB-BS918ABY)
A20: PROD1 | B20: Aguardando técnico iniciar | C20: EM_REPARO | D20: 351742730181700 | E20: OS008558 | F20: 1950192 | G20: SAMSUNG GALAXY S23 ULTRA 512GB SM-S918B CREME RECERTIFICADO | I20: aguardando_inicio | J20: 08/10/2026 17:00 | O20: BATERIA SAMSUNG GALAXY S23 ULTRA (EB-BS918ABY)
A21: PROD1 | B21: Aguardando técnico iniciar | C21: EM_REPARO | D21: 351742730332865 | E21: OS008571 | F21: 1950192 | G21: SAMSUNG GALAXY S23 ULTRA 512GB SM-S918B VERDE RECERTIFICADO | I21: aguardando_inicio | J21: 08/10/2026 17:09 | O21: BATERIA SAMSUNG GALAXY S23 ULTRA (EB-BS918ABY) - AMAZON / TAMPA SAMSUNG S23 ULTRA 5G - VERDE ESCURO / TAMPA SAMSUNG S23 ULTRA 5G - PRETO
A22: PROD1 | B22: Aguardando técnico iniciar | C22: EM_REPARO | D22: 351742730477827 | E22: OS008590 | F22: 1950192 | G22: SAMSUNG GALAXY S23 ULTRA 512GB SM-S918B VERDE RECERTIFICADO | I22: aguardando_inicio | J22: 08/10/2026 17:14 | O22: TAMPA SAMSUNG S23 ULTRA 5G - PRETO / BATERIA SAMSUNG GALAXY S23 ULTRA (EB-BS918ABY) - AMAZON
A23: PROD1 | B23: Em reparo agora | C23: EM_REPARO | D23: 356132585252431 | E23: OS007964 | F23: 61109 | G23: APPLE IPHONE SE2 64GB WHITE | H23: Victor Guilherme | I23: em_execucao | J23: 02/10/2026 09:13 | K23: 08/10/2026 09:51 | O23: BATERIA IPHONE SE 2020 SKYTECH COM FLEX / TELA IPHONE 8 - SE 2020 - SKYTECH PREMIUM - BRANCO
A24: PROD1 | B24: Em reparo agora | C24: EM_REPARO | D24: 350828561016304 | E24: OS008488 | F24: 1950192 | G24: SAMSUNG GALAXY S23 ULTRA 512GB SM-S918B VERDE RECERTIFICADO | H24: Victor Guilherme | I24: em_execucao | J24: 08/10/2026 16:35 | K24: 15/10/2026 10:21 | O24: CANETA SAMSUNG S23 ULTRA -VERDE - NACIONAL
A25: PROD1 | B25: Pausado | C25: REPARO_PAUSADO | D25: 352429897178047 | E25: OS004454 | F25: 308797 | G25: SAMSUNG GALAXY A33 5G | H25: Victor Guilherme | I25: pausado | J25: 28/09/2026 06:43 | K25: 28/09/2026 14:18 | L25: 28/09/2026 14:21
A26: PROD1 | B26: Pausado | C26: REPARO_PAUSADO | D26: 354103135981573 | E26: OS005608 | F26: 325349 | G26: SAMSUNG GALAXY S22 128GB GREEN | H26: Helen | I26: pausado | J26: 28/09/2026 06:44 | K26: 30/09/2026 10:05 | L26: 30/09/2026 12:15 | O26: TAMPA SAMSUNG S22 - PRETO
A27: PROD1 | B27: Pausado | C27: REPARO_PAUSADO | D27: 356876521688450 | E27: OS007943 | F27: 61109 | G27: APPLE IPHONE 15 PRO MAX 256GB TITANIUM BLUE | H27: Victor Guilherme | I27: pausado | J27: 02/10/2026 09:08 | K27: 08/10/2026 09:30 | L27: 08/10/2026 09:49 | O27: BATERIA APPLE IPHONE 15 PRO MAX - SKYTECH - SKYCODE
A28: PROD1 | B28: Pausado | C28: REPARO_PAUSADO | D28: 351371810397208 | E28: OS008279 | F28: 1943173 | G28: SAMSUNG GALAXY S23 ULTRA 256GB SM-S918B PRETO RECERTIFICADO | H28: Victor Guilherme | I28: pausado | J28: 05/10/2026 16:36 | K28: 07/10/2026 07:41 | L28: 07/10/2026 07:57
A29: PROD1 | B29: Pausado - pedido de peça | C29: REPARO_PAUSADO | D29: 358299384867194 | E29: OS005481 | F29: 325348 | G29: SAMSUNG GALAXY A02 32GB RED | H29: Helen | I29: pausado | J29: 28/09/2026 06:44 | K29: 30/09/2026 15:35 | L29: 02/10/2026 11:27 | O29: BATERIA SAMSUNG GALAXY A02 - A12 - A21S - A13 4G 5G - A04S - M13 4G 5G SKYTECH (EB-BA217ABY) / CAMERA FRONTAL SAMSUNG A02 / ALTO FALANTE SAMSUNG A02 - A10 - A13 4G - A20 - A30 - A40 - A50 - M20 - M30 - A7 2018
A30: PROD1 | B30: Recebido - aguardando reparo | C30: RECEBIDA | D30: 359209090027644 | E30: OS004760 | F30: 308797 | G30: SAMSUNG GALAXY J8 64GB PRETO | I30: aguardando_triagem | J30: 28/09/2026 06:43
A31: PROD1 | B31: Recebido - aguardando reparo | C31: RECEBIDA | D31: 350547661486353 | E31: OS005169 | F31: 325830 | G31: SAMSUNG GALAXY A22 128GB C1 | I31: aguardando_triagem | J31: 28/09/2026 06:44
A32: PROD1 | B32: Recebido - aguardando reparo | C32: RECEBIDA | D32: 352861981540759 | E32: OS005350 | F32: 327784 | G32: SAMSUNG GALAXY A23 64GB C1 | I32: aguardando_triagem | J32: 28/09/2026 06:44
A33: PROD1 | B33: Recebido - aguardando reparo | C33: RECEBIDA | D33: 351331724861368 | E33: OS005580 | F33: 325350 | G33: SAMSUNG GALAXY S21 FE 5G 128GB WHITE | I33: aguardando_triagem | J33: 28/09/2026 06:44
A34: PROD1 | B34: Recebido - aguardando reparo | C34: RECEBIDA | D34: 354711350440404 | E34: OS005918 | F34: 324849 | G34: SAMSUNG SM-S908E GALAXY S22 ULTRA 5G 256GB BRANCO RECERTIFICADO | I34: aguardando_triagem | J34: 28/09/2026 06:44
A35: PROD1 | B35: Recebido - aguardando reparo | C35: RECEBIDA | D35: 350389917054648 | E35: OS007192 | F35: 10254 | G35: SAMSUNG GALAXY S23 256GB PRETO - EXCELENTE | I35: aguardando_triagem | J35: 28/09/2026 12:10
A36: PROD1 | B36: Recebido - aguardando reparo | C36: RECEBIDA | D36: 354103130813854 | E36: OS007692 | F36: 2056 | G36: SAMSUNG SM-S901E GALAXY S22 5G 128GB PRETO | I36: aguardando_triagem | J36: 30/09/2026 14:49
A37: PROD1 | B37: Recebido - aguardando reparo | C37: RECEBIDA | D37: 930150707 | E37: OS007768 | F37: 2056 | G37: APARELHOS SAMSUNG | I37: aguardando_triagem | J37: 01/10/2026 09:31
A38: PROD1 | B38: Recebido - aguardando reparo | C38: RECEBIDA | D38: 351742730042175 | E38: OS008485 | F38: 1950192 | G38: SAMSUNG GALAXY S23 ULTRA 512GB SM-S918B CREME RECERTIFICADO | I38: aguardando_triagem | J38: 08/10/2026 16:32
A39: PROD1 | B39: Reparado - aguardando CQE | C39: AGUARDANDO_CQE | D39: 354396704997489 | E39: OS007853 | F39: 61109 | G39: APPLE IPHONE 11 128GB BLACK | H39: Victor Guilherme | I39: finalizado | J39: 02/10/2026 08:31 | K39: 07/10/2026 12:49 | L39: 07/10/2026 13:06 | M39: 08/10/2026 07:44 | O39: TELA IPHONE 11 - SKYTECH PRO - TROCA CI
A40: PROD1 | B40: Reparado - aguardando CQE | C40: AGUARDANDO_CQE | D40: 357032763555804 | E40: OS007979 | F40: 64156 | G40: APPLE IPHONE 13 128GB BLUE | H40: Victor Guilherme | I40: finalizado | J40: 02/10/2026 09:16 | K40: 07/10/2026 14:44 | L40: 07/10/2026 15:00 | M40: 08/10/2026 07:42 | O40: BATERIA IPHONE 13 COM FLEX - SKYTECH - SKYCODE
...
